-- Flute tests for the catch() function

-----------------------------------------------------------------------------------------------------------------------
-- Check that catch() does nothing if no error is raised.

function testCatchClean()
   local err, a, b, c = catch(function()
      local i = 1
      return 1, 2, 3, 4
   end,
   function(Exception)
      error(Exception.line .. ": An exception was raised despite doing nothing.")
   end)

   if (err != ERR_Okay) then
      error("Expected the error code to be ERR_Okay")
   end

   if not (a == 1 and b == 2 and c == 3) then
      error("Did not receive expected results from the successful function.")
   end

   local err, hello, world = catch(function()
      return 'hello', 'world'
   end)

   if hello != 'hello' or world != 'world' then
      error("Invalid results detected.")
   end
end

-----------------------------------------------------------------------------------------------------------------------
-- Check that a standard error() will result in the exception being caught.

function testCatch()
   local exception_raised = false

   local err = catch(function()
      error("Catch this! (Exception raised on purpose)")
   end,
   function(Exception)
      print(Exception.line .. ": Caught exception '" .. Exception.message .. "'")
      exception_raised = true
   end)

   if (err != ERR_Exception) then
      error("Expected the error code to be ERR_Exception")
   end

   if (exception_raised != true) then
      error("Failed to catch the raised exception.")
   end
end

-----------------------------------------------------------------------------------------------------------------------
-- Check that an ERROR result other than ERR_Okay will result in the generation of an exception.

function testCatchErrorCode()
   local exception_raised = false

   local err, result = catch(function()
      mSys.AllocMemory(-10, 0)
   end,
   function(Exception)
      print(Exception.line .. ": Caught exception as expected, error code #" .. Exception.code .. " '" .. Exception.message .. "'")
      exception_raised = true
   end)

   if (result != nil) then
      error("The result is not empty.")
   end

   if (err != ERR_Args) then
      error("Expected the error code to be ERR_Args")
   end

   if (exception_raised != true) then
      error("Failed to catch the raised exception.")
   end
end

-----------------------------------------------------------------------------------------------------------------------
-- Check that obj.new() raises exceptions correctly.

function testCatchObject()
   local exception_raised = false

   local err, result = catch(function()
      local fl = obj.new("file", { path="File does not exist" })
   end,
   function(Exception)
      print(Exception.line .. ": Caught exception as expected, error code #" .. Exception.code .. " '" .. Exception.message .. "'")
      exception_raised = true
   end)

   if (exception_raised != true) then
      error("Failed to catch the raised exception.")
   end
end

-----------------------------------------------------------------------------------------------------------------------
-- Check that object actions raise exceptions correctly.

function testCatchObjectAction()
   local exception_raised = false

   local err, result = catch(function()
      local time = obj.new("time", { })
      time.acUndo()
   end,
   function(Exception)
      print(Exception.line .. ": Caught exception as expected, error code #" .. Exception.code .. " '" .. Exception.message .. "'")
      exception_raised = true
   end)

   if (exception_raised != true) then
      error("Failed to catch the raised exception.")
   end
end

-----------------------------------------------------------------------------------------------------------------------
-- Check that errors returned from writing to object fields are caught.

function testSetField()
   local exception_raised = false

   local err, result = catch(function()
      local time = obj.new("time", { })
      time.madeup_field = -1
   end,
   function(Exception)
      print(Exception.line .. ": Caught exception as expected, error code #" .. Exception.code .. " '" .. Exception.message .. "'")
      exception_raised = true
   end)

   if (exception_raised != true) then
      error("Failed to catch the raised exception.")
   end
end

-----------------------------------------------------------------------------------------------------------------------
-- Test that filtering for error codes works.

function testCatchFilter()
   catch(function()
      catch(function()
         local pic, err = obj.new("picture", { src="nowhere:nofile.png" })
         print("Received error " .. err)
      end,
      { ERR_CreateObject, ERR_Init, ERR_File },
      function(Exception)
         print(Exception.line .. ": Caught filtered exception #" .. Exception.code)
      end)
   end,
   function(Exception) // This will be triggered if the filter doesn't catch the specified error codes.
      error("Failed to filter for the expected error code, received code " .. Exception.code)
   end)
end

-----------------------------------------------------------------------------------------------------------------------
-- Test that unfiltered errors are thrown to the parent block.

function testMissedFilter()
   local status, msg = pcall(function()
      catch(function()
         local xml = obj.new("xml", { flags="NEW" })
         xml.acDraw()
         print("This must not be reached.")
      end,
      { ERR_Failed }, // Filter for the wrong error code.
      function(Exception)
         // Do nothing
      end)
   end)

   if (status == false) then
      // Exception has been thrown to the parent as expected
   else
      error("The exception was not thrown to the parent block.")
   end
end

-----------------------------------------------------------------------------------------------------------------------
-- Test simple catch() with no function defined to handle the exception.

function testNoThrow()
   local ex, result = catch(function()
      error("Catch this! (Exception raised on purpose)")
   end)

   if (ex == nil) then
      error("Exception table was not returned.")
   else
      print("Received line " .. ex.line .. ", code " .. nz(ex.code,"LUA") .. ", msg: " .. ex.message)
   end
end

-----------------------------------------------------------------------------------------------------------------------

   return {
      tests = {
         'testCatchClean', 'testCatch', 'testCatchErrorCode',
         'testCatchFilter', 'testMissedFilter', 'testCatchObject',
         'testCatchObjectAction', 'testNoThrow', 'testSetField'
      }
   }
